#VRML_SIM R2023b utf8

EXTERNPROTO "https://raw.githubusercontent.com/cyberbotics/webots/R2023b/projects/objects/backgrounds/protos/TexturedBackground.proto"
EXTERNPROTO "https://raw.githubusercontent.com/cyberbotics/webots/R2023b/projects/objects/backgrounds/protos/TexturedBackgroundLight.proto"
EXTERNPROTO "https://raw.githubusercontent.com/cyberbotics/webots/R2023b/projects/objects/floors/protos/RectangleArena.proto"
EXTERNPROTO "https://raw.githubusercontent.com/cyberbotics/webots/R2023b/projects/appearances/protos/Parquetry.proto"
EXTERNPROTO "https://raw.githubusercontent.com/cyberbotics/webots/R2023b/projects/appearances/protos/BrushedAluminium.proto"

WorldInfo {
  basicTimeStep 64
}
Viewpoint {
  orientation -0.5572088668033137 0.5454924174274919 0.6260641351210575 2.041896250867406
  position -0.03647819759087484 -1.655356715707301 14.096991388258301
}
TexturedBackground {
}
TexturedBackgroundLight {
  luminosity 0.7
  castShadows FALSE
}
RectangleArena {
  floorSize 5 6
  floorTileSize 6 6
  floorAppearance Parquetry {
    type "light strip"
  }
  wallThickness 0.1
  wallHeight 0.5
  wallAppearance BrushedAluminium {
    IBLStrength 5
  }
}
Solid {
  translation 1.09 -0.82 0.1
  rotation 0 0 1 0.523599
  children [
    DEF box Shape {
      appearance PBRAppearance {
        baseColor 0.6 0.2 1
        metalness 0
      }
      geometry Box {
        size 0.2 0.2 0.2
      }
    }
  ]
  name "solid(8)"
  boundingObject USE box
}
Solid {
  translation 1.91 -0.45 0.1
  rotation 0 0 1 0.261799
  children [
    DEF box Shape {
      appearance PBRAppearance {
        baseColor 1 0.5 0
        metalness 0
      }
      geometry Box {
        size 0.2 0.2 0.2
      }
    }
  ]
  name "solid(7)"
  boundingObject USE box
}
Solid {
  translation 2.33 -1.53 0.1
  rotation 0 0 1 -0.785395307179586
  children [
    DEF box Shape {
      appearance PBRAppearance {
        baseColor 0.8 1 0.3
        metalness 0
      }
      geometry Box {
        size 0.2 0.2 0.2
      }
    }
  ]
  name "solid(6)"
  boundingObject USE box
}
Solid {
  translation 1.96 1.91816 0.25
  rotation 0 0 1 2.61799
  children [
    DEF box Shape {
      appearance PBRAppearance {
        baseColor 0 0 0
        metalness 0
      }
      geometry Box {
        size 1 0.2 0.5
      }
    }
  ]
  name "solid(9)"
  boundingObject USE box
}
Robot {
  translation 0.91 0.33 0.059
  rotation 0 0 1 -1.5707953071795862
  children [
    Solid {
      translation 0.1 0 0.04
      children [
        DEF button Shape {
          appearance PBRAppearance {
            baseColor 0.8 0.3 0
            metalness 0
          }
          geometry Cylinder {
            height 0.02
            radius 0.02
          }
        }
      ]
      boundingObject USE button
    }
    Pen {
      translation 0 0 -0.058
      inkColor 0 0 0.8
      inkDensity 0.6613971373638111
      leadSize 0.2
    }
    Lidar {
      translation 0.169 0 -0.03
      horizontalResolution 200
      fieldOfView 3.14159
      numberOfLayers 1
    }
    Display {
      rotation 0 0 1 3.14
      width 600
      height 700
    }
    Pose {
      children [
        DEF body Shape {
          appearance PBRAppearance {
            baseColor 1 0 0
            metalness 0
          }
          geometry Cylinder {
            height 0.088
            radius 0.169
          }
        }
      ]
    }
    HingeJoint {
      jointParameters HingeJointParameters {
        axis 0 1 0
        anchor 0 0 -0.018
      }
      device [
        RotationalMotor {
          name "right_motor"
          consumptionFactor -0.001
          maxVelocity 15
        }
        PositionSensor {
          name "right_position"
        }
      ]
      endPoint Solid {
        translation 0 -0.13 -0.018
        rotation 0.20796171599720592 -0.6916460114586965 0.6916485520210204 2.731515710561949
        children [
          Pose {
            rotation 1 0 0 0
            children [
              DEF wheel Shape {
                appearance PBRAppearance {
                  baseColor 0 0 0
                  metalness 0
                }
                geometry Cylinder {
                  height 0.02
                  radius 0.04
                }
              }
            ]
          }
        ]
        name "right wheel"
        boundingObject DEF wheel Shape {
          appearance PBRAppearance {
            baseColor 0 0 0
            metalness 0
          }
          geometry Cylinder {
            height 0.02
            radius 0.04
          }
        }
      }
    }
    HingeJoint {
      jointParameters HingeJointParameters {
        axis 0 1 0
        anchor 0 0 -0.018
      }
      device [
        RotationalMotor {
          name "left_motor"
          consumptionFactor -0.001
          maxVelocity 15
        }
        PositionSensor {
          name "left_position"
        }
      ]
      endPoint Solid {
        translation 0 0.13 -0.018
        rotation 0.20796171599720642 -0.6916460114586961 0.6916485520210206 2.7315157105619505
        children [
          Pose {
            rotation 1 0 0 0
            children [
              DEF wheel Shape {
                appearance PBRAppearance {
                  baseColor 0 0 0
                  metalness 0
                }
                geometry Cylinder {
                  height 0.02
                  radius 0.04
                }
              }
            ]
          }
        ]
        name "left wheel"
        boundingObject DEF wheel Shape {
          appearance PBRAppearance {
            baseColor 0 0 0
            metalness 0
          }
          geometry Cylinder {
            height 0.02
            radius 0.04
          }
        }
      }
    }
  ]
  boundingObject USE body
  controller "<extern>"
}
Solid {
  translation 1.58 0 0.25
  children [
    DEF box Shape {
      appearance PBRAppearance {
        metalness 0.5
      }
      geometry Box {
        size 2 0.1 0.5
      }
    }
  ]
  name "solid(1)"
  boundingObject USE box
}
Solid {
  translation 1.92 -2.23 0.25
  children [
    DEF box Shape {
      appearance PBRAppearance {
        metalness 0.5
      }
      geometry Box {
        size 1.2 0.1 0.5
      }
    }
  ]
  name "solid(3)"
  boundingObject USE box
}
Solid {
  translation -1.33 0 0.24
  children [
    DEF box Shape {
      appearance PBRAppearance {
        metalness 0.5
      }
      geometry Box {
        size 2.5 0.1 0.5
      }
    }
  ]
  boundingObject USE box
}
Solid {
  translation -1.95 -0.56 0.1
  children [
    DEF box Shape {
      appearance PBRAppearance {
        baseColor 0.1 1 0.2
        metalness 0
      }
      geometry Box {
        size 1 0.7 0.2
      }
    }
  ]
  name "solid(5)"
  boundingObject USE box
}
Solid {
  translation 0 2.32 0.25
  children [
    DEF box Shape {
      appearance PBRAppearance {
        metalness 0.5
      }
      geometry Box {
        size 5 0.1 0.5
      }
    }
  ]
  name "solid(4)"
  boundingObject USE box
}
Solid {
  translation -0.76 -2.23 0.24
  children [
    DEF box Shape {
      appearance PBRAppearance {
        metalness 0.5
      }
      geometry Box {
        size 3.5 0.1 0.5
      }
    }
  ]
  name "solid(2)"
  boundingObject USE box
}
Solid {
  translation 0.19 0.94 0.25
  children [
    DEF cyl Shape {
      appearance PBRAppearance {
        metalness 0.5
      }
      geometry Cylinder {
        height 0.5
        radius 0.1
      }
      castShadows FALSE
    }
  ]
  name "solid(10)"
  boundingObject USE cyl
}
