#VRML_SIM R2023b utf8

EXTERNPROTO "https://raw.githubusercontent.com/cyberbotics/webots/R2023b/projects/objects/backgrounds/protos/TexturedBackground.proto"
EXTERNPROTO "https://raw.githubusercontent.com/cyberbotics/webots/R2023b/projects/objects/backgrounds/protos/TexturedBackgroundLight.proto"
EXTERNPROTO "https://raw.githubusercontent.com/cyberbotics/webots/R2023b/projects/objects/floors/protos/RectangleArena.proto"
EXTERNPROTO "https://raw.githubusercontent.com/cyberbotics/webots/R2023b/projects/appearances/protos/Parquetry.proto"
EXTERNPROTO "https://raw.githubusercontent.com/cyberbotics/webots/R2023b/projects/appearances/protos/BrushedAluminium.proto"

WorldInfo {
  basicTimeStep 64
}
Viewpoint {
  orientation 0.5444910574455345 -0.5300832980264756 -0.6500316803935159 4.270009340765356
  position 1.3343749176136863 -1.981041526401353 9.595407137040793
}
RectangleArena {
  floorSize 5 4
  floorTileSize 5 5
  floorAppearance Parquetry {
    type "light strip"
  }
  wallThickness 0.1
  wallHeight 0.5
  wallAppearance BrushedAluminium {
    IBLStrength 5
  }
}
Solid {
  translation 0 -0.33 0.0499938
  rotation 0.5773509358560258 -0.577349935856137 0.577349935856137 2.09439
  children [
    DEF carpet Shape {
      appearance PBRAppearance {
        baseColor 0.7 0.1 0.8
        metalness 0
      }
      geometry Cylinder {
        height 3
        radius 0.05
      }
    }
  ]
  name "solid(5)"
  boundingObject USE carpet
}
Solid {
  translation 1.4 -0.33 0.0499897
  rotation 0.5773509358560258 -0.577349935856137 0.577349935856137 2.09439
  children [
    DEF carpet Shape {
      appearance PBRAppearance {
        baseColor 1 0.7 0.2
        metalness 0
      }
      geometry Cylinder {
        height 3
        radius 0.05
      }
    }
  ]
  name "solid(3)"
  boundingObject USE carpet
}
Solid {
  translation -1.4 -0.33 0.05
  rotation 0.5773509358560258 -0.577349935856137 0.577349935856137 2.09439
  children [
    DEF carpet Shape {
      appearance PBRAppearance {
        baseColor 0.5 0.9 0.3
        metalness 0
      }
      geometry Cylinder {
        height 3
        radius 0.05
      }
    }
  ]
  name "solid(8)"
  boundingObject USE carpet
}
Solid {
  translation 2.1 -1.02 0.25
  children [
    DEF box Shape {
      appearance PBRAppearance {
        metalness 0.5
      }
      geometry Box {
        size 0.04 2 0.5
      }
    }
  ]
  name "solid(2)"
  boundingObject USE box
}
Solid {
  translation 2.1 1.16 0.25
  children [
    DEF box Shape {
      appearance PBRAppearance {
        metalness 0.5
      }
      geometry Box {
        size 0.04 1.7 0.5
      }
    }
  ]
  name "solid(1)"
  boundingObject USE box
}
Solid {
  translation 0.7 0.43 0.25
  children [
    DEF box Shape {
      appearance PBRAppearance {
        metalness 0.5
      }
      geometry Box {
        size 0.04 3.24 0.5
      }
    }
  ]
  name "solid(6)"
  boundingObject USE box
}
Solid {
  translation -0.7 0.49 0.25
  children [
    DEF box Shape {
      appearance PBRAppearance {
        metalness 0.5
      }
      geometry Box {
        size 0.04 3.24 0.5
      }
    }
  ]
  name "solid(4)"
  boundingObject USE box
}
Solid {
  translation -2.32 0.38 0.25
  children [
    DEF box Shape {
      appearance PBRAppearance {
        metalness 0.5
      }
      geometry Box {
        size 0.37 3.24 0.5
      }
    }
  ]
  boundingObject USE box
}
Robot {
  translation 1.64 -1.03 0.059
  children [
    Solid {
      translation 0.1 0 0.04
      children [
        DEF button Shape {
          appearance PBRAppearance {
            baseColor 0.8 0.3 0
            metalness 0
          }
          geometry Cylinder {
            height 0.02
            radius 0.02
          }
        }
      ]
      boundingObject USE button
    }
    Pen {
      translation 0 0 -0.058
      inkColor 0 0 0.8
      inkDensity 0.6613971373638111
      leadSize 0.2
      write FALSE
    }
    Lidar {
      translation 0.169 0 -0.03
      horizontalResolution 200
      fieldOfView 3.14159
      numberOfLayers 1
      maxRange 5
    }
    Display {
      rotation 0 0 1 3.14
      width 600
      height 500
    }
    Pose {
      children [
        DEF body Shape {
          appearance PBRAppearance {
            baseColor 1 0 0
            metalness 0
          }
          geometry Cylinder {
            height 0.088
            radius 0.169
          }
        }
      ]
    }
    HingeJoint {
      jointParameters HingeJointParameters {
        axis 0 1 0
        anchor 0 0 -0.018
      }
      device [
        RotationalMotor {
          name "right_motor"
          consumptionFactor -0.001
          maxVelocity 15
        }
        PositionSensor {
          name "right_position"
        }
      ]
      endPoint Solid {
        translation 0 -0.13 -0.018
        rotation 0.20796171599720592 -0.6916460114586965 0.6916485520210204 2.731515710561949
        children [
          Pose {
            rotation 1 0 0 0
            children [
              DEF wheel Shape {
                appearance PBRAppearance {
                  baseColor 0 0 0
                  metalness 0
                }
                geometry Cylinder {
                  height 0.02
                  radius 0.04
                }
              }
            ]
          }
        ]
        name "right wheel"
        boundingObject DEF wheel Shape {
          appearance PBRAppearance {
            baseColor 0 0 0
            metalness 0
          }
          geometry Cylinder {
            height 0.02
            radius 0.04
          }
        }
      }
    }
    HingeJoint {
      jointParameters HingeJointParameters {
        axis 0 1 0
        anchor 0 0 -0.018
      }
      device [
        RotationalMotor {
          name "left_motor"
          consumptionFactor -0.001
          maxVelocity 15
        }
        PositionSensor {
          name "left_position"
        }
      ]
      endPoint Solid {
        translation 0 0.13 -0.018
        rotation 0.20796171599720636 -0.6916460114586961 0.6916485520210206 2.7315157105619505
        children [
          Pose {
            rotation 1 0 0 0
            children [
              DEF wheel Shape {
                appearance PBRAppearance {
                  baseColor 0 0 0
                  metalness 0
                }
                geometry Cylinder {
                  height 0.02
                  radius 0.04
                }
              }
            ]
          }
        ]
        name "left wheel"
        boundingObject DEF wheel Shape {
          appearance PBRAppearance {
            baseColor 0 0 0
            metalness 0
          }
          geometry Cylinder {
            height 0.02
            radius 0.04
          }
        }
      }
    }
  ]
  boundingObject USE body
  controller "<extern>"
}
TexturedBackground {
}
TexturedBackgroundLight {
  luminosity 0.7
  castShadows FALSE
}
